Workbook

Sheet Anleitung
A1: Damicon: Manueller Rollentest
A3: Stand | B3: 20.09.2026
A4: Umfang | B4: 43 Testfaelle ueber 7 Rollen, davon 11 Negativtests
A5: Dauer | B5: 3 bis 4 Stunden ohne Fehlerverfolgung
A6: Umgebung | B6: https://damicon.vercel.app/de/dashboard
A8: 1. VORBEREITUNG
B9: Die Instanz verlangt eine ANMELDUNG. Es gibt keine freie Demo-Ansicht.
B10: Im Projekt sind sieben Demo-Konten vorgesehen (supabase/seed-auth.mjs), Passwort steht im selben Skript.
B11: OB DIESE KONTEN AUF DER VERCEL-INSTANZ EXISTIEREN, IST NICHT GEPRUEFT. Vor Testbeginn klaeren.
B12: Fehlen sie: entweder Admin legt sie an, oder lokal im Demo-Modus testen (npm run dev ohne Supabase).
B13: ACHTUNG: weder der Demo-Modus noch "Ansicht als" beantworten die Negativtests. Beide aendern nur die Anzeige,
B14: nicht die Rechtepruefung der Datenbank. Dafuer muss man sich echt mit dem jeweiligen Konto anmelden.
B15: Browser: je Rolle ein eigenes privates Fenster, sonst ueberlagern sich die Anmeldungen.
B16: Mobil: Brigade und Pfluecker mindestens je einen Testfall am Handy oder bei 390 px Fensterbreite.
A18: 2. REIHENFOLGE (vier Faelle bauen aufeinander auf)
B19: Admin TF-A2 (Kunden einladen) liefert den Code fuer Kunde TF-K1
B20: Betriebsleitung TF-L1 (Aufgabe anlegen) liefert die Aufgabe fuer Brigade TF-B1 bis TF-B3
B21: Betriebsleitung TF-L4 (Beleg pruefen) macht sie abrechenbar fuer Buchhaltung TF-F2
B22: Kunde TF-K5 (Reklamation) liefert den Vorgang fuer Buchhaltung TF-F6
B23: Alle uebrigen Testfaelle sind unabhaengig.
A25: 3. AUSFUELLEN
B26: Spalte Ergebnis: Auswahlliste mit OK / NOK / blockiert / offen. Faerbt sich automatisch.
B27: Spalte Beobachtung: nur bei NOK oder blockiert. Was stand am Bildschirm, nicht die Deutung.
B28: Spalte Datum/Tester: Kuerzel genuegt.
B29: Bei NOK zusaetzlich: Bildschirmfoto als TF-<Nr>.png, Uhrzeit notieren, zweiten Versuch machen.
B30: Explorativ: die Schritte sind die Pflicht, nicht die Grenze. Auffaelliges ins Blatt "Funde".
A32: 4. FEHLERKLASSEN
A33: S1 | B33: Datenverlust, falsche Zahl auf einem Beleg, jemand sieht Fremddaten
A34: S2 | B34: Kernfunktion nicht nutzbar, kein Umweg
A35: S3 | B35: Funktion nutzbar, aber fehlerhaft oder umstaendlich
A36: S4 | B36: Schoenheitsfehler: Tippfehler, Abstand, Farbe
B37: Falsche Zahlen in Lohn, Rechnung oder Steuer sind IMMER mindestens S2.
A39: 5. WAS KEIN FEHLER IST (nicht melden)
B40: Lieferschein-ESF und Integrationen sind Platzhalter, es liest und schreibt sie noch nichts.
B41: Wetter zeigt die Temperatursumme, trifft bewusst keine Vorhersage.
B42: Vorbestellungen bestaetigt das Buero von Hand, es gibt keine Automatik.
B43: QR-Steigen kann nur anzeigen und drucken, Steigen entstehen ueber die Pflueckaufgabe.
B44: Kanaele sind reine Anzeige, keine echte Anbindung an WhatsApp oder Kaspi.
B45: Hinweis "Beispieldaten" = keine Datenbank hinterlegt, Meldung der Umgebung.
B46: ABER: Hinweis "Fehler" statt "Beispieldaten" IST zu melden, dann ist eine Abfrage fehlgeschlagen.
...

Sheet Auswertung
A1: Auswertung (rechnet sich aus den Rollenblaettern)
A3: Rolle | B3: Testfaelle | C3: OK | D3: NOK | E3: blockiert | F3: offen
A4: Admin | B4: 7 | C4: =COUNTIF(Admin!F6:F12,"OK") | D4: =COUNTIF(Admin!F6:F12,"NOK") | E4: =COUNTIF(Admin!F6:F12,"blockiert") | F4: =B4-C4-D4-E4
A5: Betriebsleitung | B5: 6 | C5: =COUNTIF(Betriebsleitung!F6:F11,"OK") | D5: =COUNTIF(Betriebsleitung!F6:F11,"NOK") | E5: =COUNTIF(Betriebsleitung!F6:F11,"blockiert") | F5: =B5-C5-D5-E5
A6: Buchhaltung | B6: 7 | C6: =COUNTIF(Buchhaltung!F6:F12,"OK") | D6: =COUNTIF(Buchhaltung!F6:F12,"NOK") | E6: =COUNTIF(Buchhaltung!F6:F12,"blockiert") | F6: =B6-C6-D6-E6
A7: Brigade | B7: 6 | C7: =COUNTIF(Brigade!F6:F11,"OK") | D7: =COUNTIF(Brigade!F6:F11,"NOK") | E7: =COUNTIF(Brigade!F6:F11,"blockiert") | F7: =B7-C7-D7-E7
A8: Pfluecker | B8: 5 | C8: =COUNTIF(Pfluecker!F6:F10,"OK") | D8: =COUNTIF(Pfluecker!F6:F10,"NOK") | E8: =COUNTIF(Pfluecker!F6:F10,"blockiert") | F8: =B8-C8-D8-E8
A9: Erzeuger (Nachbarbetrieb) | B9: 5 | C9: =COUNTIF(Erzeuger!F6:F10,"OK") | D9: =COUNTIF(Erzeuger!F6:F10,"NOK") | E9: =COUNTIF(Erzeuger!F6:F10,"blockiert") | F9: =B9-C9-D9-E9
A10: B2B-Kunde | B10: 7 | C10: =COUNTIF(Kunde!F6:F12,"OK") | D10: =COUNTIF(Kunde!F6:F12,"NOK") | E10: =COUNTIF(Kunde!F6:F12,"blockiert") | F10: =B10-C10-D10-E10
A11: Summe | B11: =SUM(B4:B10) | C11: =SUM(C4:C10) | D11: =SUM(D4:D10) | E11: =SUM(E4:E10) | F11: =SUM(F4:F10)
A13: Die Zahlen fuellen sich von selbst, sobald in den Rollenblaettern die Spalte
A14: "Ergebnis" gesetzt wird. Nichts hier von Hand eintragen.

Sheet Admin
A1: Damicon Testfaelle - Rolle: Admin
A2: Anmeldung als: admin@damicon.demo
A3: Einzige Rolle mit Vollzugriff. Geprueft wird vor allem, ob die Rechteverwaltung selbst stimmt, denn jeder Fehler hier wirkt auf alle anderen Rollen.
A5: Nr | B5: Was geprueft wird | C5: Schritte | D5: Testdaten (Eingabe) | E5: Erwartetes Ergebnis | F5: Ergebnis | G5: Beobachtung | H5: Datum / Tester
A6: TF-A1 | B6: Rechtematrix ist vollstaendig und stimmt | C6: 1. Buero > Rollen oeffnen 2. Rechtematrix aufklappen 3. Zeile "Lohn" suchen 4. Spalten Pfluecker und Brigade vergleichen | D6: keine Eingabe | E6: Alle 7 Rollen sind gelistet. Pfluecker hat bei Lohn nur "ansehen", Brigade hat bei Lohn gar kein Recht. Die Matrix zeigt die tatsaechliche Konfiguration, keine feste Grafik.
A7: TF-A2 | B7: Kundenzugang ausstellen | C7: 1. Buero > Rollen > Kundenzugaenge 2. "Einladung ausstellen" 3. Felder fuellen 4. Absenden 5. Angezeigten Code notieren | D7: B2B-Kunde: Almaty Fresh Market Name: TEST Aigul Sarsenowa E-Mail: test.kunde.20092026@example.com | E7: Einladung wird angelegt, ein Code erscheint. Hinweis "gilt 14 Tage und nur fuer diese Adresse". CODE HIER NOTIEREN, wird in TF-K1 gebraucht.
A8: TF-A3 | B8: "Ansicht als" wirkt auf die Anzeige | C8: 1. Oben rechts Rollenumschalter 2. Auf "Pfluecker" umstellen 3. Navigation ansehen 4. Zurueck auf Admin | D8: Rolle: Pfluecker | E8: Die Navigation schrumpft sichtbar auf Dashboard, Lohn und Schulungen. Feld, Hof und Markt verschwinden. Nach dem Zuruecksetzen ist wieder alles da.
A9: TF-A4 | B9: KI-Anbieter verwalten (nur Admin) | C9: 1. KI-Bereich oeffnen 2. Anbieterliste aufrufen 3. Pruefen, ob Anbieter anlegbar/aenderbar sind | D9: nichts speichern, nur pruefen ob erreichbar | E9: Die Anbieterverwaltung ist erreichbar und bedienbar. Kein Schluessel wird im Klartext angezeigt.
A10: TF-A5 | B10: Steuernummer mit falscher Pruefziffer wird abgelehnt (NEGATIVTEST) | C10: 1. Buero > Stammdaten 2. Betrieb bearbeiten, Rechtsform KH/FH (Feld heisst dann IIN) 3. Wert 1 eintragen, speichern 4. Wert 2 eintragen, speichern 5. Wert 3 eintragen, speichern | D10: 1. zu kurz: 78062130045 2. Pruefziffer falsch: 780621300451 3. gueltig: 780621300453 | E10: Wert 1 abgelehnt mit Hinweis auf die Stellenzahl. Wert 2 abgelehnt mit Hinweis auf die PRUEFZIFFER, das ist eine andere Meldung als bei Wert 1. Wert 3 wird gespeichert. Wird Wert 1 oder 2 angenommen: S1.
A11: TF-A6 | B11: Auditprotokoll und MFA-Status | C11: 1. Buero > Compliance 2. Auditprotokoll oeffnen 3. Nach dem Eintrag aus TF-A2 suchen 4. MFA-Status ansehen | D11: Suchzeitraum: heute | E11: Die in TF-A2 ausgestellte Einladung taucht als Eintrag auf, mit Zeit und handelndem Benutzer. Der MFA-Status je Konto ist erkennbar.
A12: TF-A7 | B12: Admin sieht alle vier Zonen | C12: 1. Navigation durchgehen 2. Je ein Modul aus Feld, Hof, Buero, Markt oeffnen | D12: Feld: Reihenbloecke Hof: Kuehlkette Buero: Finanzen Markt: Preislisten | E12: Alle vier Module oeffnen ohne Zugriffsmeldung und zeigen Inhalte.
E14: Zwischenstand: | F14: =COUNTIF(F6:F12,"OK") | G14: OK von 7
F15: =COUNTIF(F6:F12,"NOK") | G15: NOK von 7
F16: =COUNTIF(F6:F12,"blockiert") | G16: blockiert von 7
A18: Freie Funde (alles Auffaellige ausserhalb der Testfaelle):
A24: Gesamteindruck in zwei Saetzen: Koennte diese Person damit arbeiten?

Sheet Betriebsleitung
A1: Damicon Testfaelle - Rolle: Betriebsleitung
A2: Anmeldung als: leitung@damicon.demo
A3: Wichtigster Test ist die Wartezeitsperre: nach einer Pflanzenschutzbehandlung darf auf dem Block gesetzlich nicht geerntet werden, und das System muss das von sich aus verhindern. TF-L2 sperrt, TF-L3 prueft die Wirkung, beide gehoeren zusammen.
A5: Nr | B5: Was geprueft wird | C5: Schritte | D5: Testdaten (Eingabe) | E5: Erwartetes Ergebnis | F5: Ergebnis | G5: Beobachtung | H5: Datum / Tester
A6: TF-L1 | B6: Pflueckaufgabe anlegen und zuweisen | C6: 1. Feld > Pflueckaufgaben 2. "Neue Pflueckaufgabe" 3. Felder fuellen 4. "Aufgabe anlegen" | D6: Reihenblock: T-N-A-01 Brigade: Brigade Nord Zielmenge in kg: 120 | E6: Aufgabe erscheint mit Status "offen" und Brigade Nord. Wird in TF-B1 gebraucht.
A7: TF-L2 | B7: Behandlung erfassen sperrt den Block automatisch | C7: 1. Feld > Pflanzenschutz 2. "Behandlung erfassen" 3. Felder fuellen, speichern 4. Feld > Reihenbloecke oeffnen, Block T-N-A-03 suchen | D7: Reihenblock: T-N-A-03 Mittel: Signum Behandelt am: heute Aufwandmenge: 1,5 Einheit: kg/ha Durchgefuehrt von: TEST Betriebsleitung | E7: Block T-N-A-03 steht danach auf Status "wartezeitgesperrt" und zeigt ein "Frei ab"-Datum in der Zukunft. Niemand musste den Status von Hand setzen.
A8: TF-L3 | B8: Gesperrter Block laesst sich nicht bepfluecken (NEGATIVTEST) | C8: 1. Feld > Pflueckaufgaben 2. "Neue Pflueckaufgabe" 3. Auswahlliste Reihenblock oeffnen 4. Nach T-N-A-03 suchen | D8: Reihenblock T-N-A-03 versuchen | E8: Der gesperrte Block erscheint GAR NICHT in der Auswahl. Laesst sich eine Aufgabe darauf anlegen: S1 (Ernte trotz gesetzlicher Wartezeit).
A9: TF-L4 | B9: Fotobeleg pruefen und Aufgabe abschliessen | C9: 1. Feld > Pflueckaufgaben 2. Aufgabe im Status "Belegpruefung" oeffnen (entsteht in TF-B3) 3. Fotobeleg ansehen 4. Aufgabe abschliessen | D9: keine Eingabe, nur Freigabe | E9: Status wechselt auf "abgeschlossen". Erst jetzt ist die Aufgabe fuer die Lohnabrechnung (TF-F2) verwertbar. Ohne Foto darf kein Abschluss moeglich sein.
A10: TF-L5 | B10: Rotationsplan zeigt den naechsten Pfluecktermin | C10: 1. Feld > Rotationsplan 2. Plantage waehlen 3. Eintrag zu T-N-A-03 suchen | D10: Plantage: Plantage Talgar | E10: Der Plan zeigt je Reihenblock den naechsten Termin im Rhythmus von 2 bis 3 Tagen. Der in TF-L2 gesperrte Block ist als gesperrt gekennzeichnet oder ausgenommen, nicht normal eingeplant.
A11: TF-L6 | B11: Lohn ist nur lesbar, nicht aenderbar (NEGATIVTEST) | C11: 1. Buero > Lohn oeffnen 2. Nach "Freigeben", "Satz anlegen" oder "Periode berechnen" suchen | D11: keine Eingabe | E11: Abrechnungen sind sichtbar, aber es gibt keine Schaltflaeche zum Anlegen, Berechnen oder Freigeben. Lohn gehoert der Buchhaltung. Erscheint eine solche Schaltflaeche und funktioniert sie: S1.
E13: Zwischenstand: | F13: =COUNTIF(F6:F11,"OK") | G13: OK von 6
F14: =COUNTIF(F6:F11,"NOK") | G14: NOK von 6
F15: =COUNTIF(F6:F11,"blockiert") | G15: blockiert von 6
A17: Freie Funde (alles Auffaellige ausserhalb der Testfaelle):
A23: Gesamteindruck in zwei Saetzen: Koennte diese Person damit arbeiten?

Sheet Buchhaltung
A1: Damicon Testfaelle - Rolle: Buchhaltung
A2: Anmeldung als: buchhaltung@damicon.demo
A3: Hier entstehen Zahlen, die auf Belegen landen. Jede Abweichung in einem Betrag ist mindestens S2, auch wenn sie klein wirkt. TF-F2 braucht eine abgeschlossene Pflueckaufgabe aus TF-L4.
A5: Nr | B5: Was geprueft wird | C5: Schritte | D5: Testdaten (Eingabe) | E5: Erwartetes Ergebnis | F5: Ergebnis | G5: Beobachtung | H5: Datum / Tester
A6: TF-F1 | B6: Lohnsatz anlegen | C6: 1. Buero > Lohn 2. "Neuen Lohnsatz anlegen" 3. Felder fuellen 4. "Satz anlegen" 5. Gegenprobe: denselben Satz noch einmal anlegen | D6: Gueltig ab: 01.10.2026 Stundenlohn: 900 Tenge kg-Satz: 850 Tenge Ziel-Ausschussquote: 5 % Faktor min: 0,90 Faktor max: 1,10 | E6: Satz wird gespeichert und erscheint in der Historie. Ein zweiter Satz mit demselben "Gueltig ab" muss ABGELEHNT werden, das ist die Eindeutigkeitsregel.
A7: TF-F2 | B7: Periode berechnen mit Qualitaetsfaktor | C7: 1. Buero > Lohn 2. "Periode berechnen" 3. Zeitraum waehlen 4. Berechnen 5. "Positionen je Pflueckaufgabe" oeffnen | D7: Zeitraum: laufender Monat Brigade: Brigade Nord | E7: Je Pfluecker entsteht eine Abrechnung. Der Qualitaetsfaktor ist sichtbar und liegt zwischen 0,90 und 1,10. Bei genau 5 % Ausschuss muss er 1,00 sein. Fehlt der Faktor oder liegt er ausserhalb: S2.
A8: TF-F3 | B8: Gesetzliche Abzuege Kasachstan rechnen korrekt | C8: 1. Buero > Lohn > "Monatsabzuege berechnen" 2. Fall A eingeben, berechnen, vergleichen 3. Mit Fall B wiederholen 4. Mit Fall C wiederholen | D8: Fall A Brutto: 250000 Fall B Brutto: 150000 Fall C Brutto: 100000 | E8: A: OPV 25.000,00 | VOSMS 5.000,00 | IPN-Grundlage 90.250,00 | IPN 9.025,00 | NETTO 210.975,00 | OPVR 8.750,00 B: OPV 15.000,00 | VOSMS 3.000,00 | Grundlage 2.250,00 | IPN 225,00 | NETTO 131.775,00 C: OPV 10.000,00 | VOSMS 2.000,00 | Grundlage 0,00 | IPN 0,00 | NETTO 88.000,00 Fall C ist der wichtige: der Freibetrag von 129.750 Tenge darf nicht ins Minus laufen.
A9: TF-F4 | B9: Freigabe und Ruecknahme der Freigabe | C9: 1. Eine berechnete Abrechnung oeffnen 2. "Freigeben" 3. Ruecknahme der Freigabe versuchen 4. "Als ausgezahlt markieren" | D9: keine Eingabe | E9: Nach der Freigabe wechselt der Status sichtbar. Die Ruecknahme verlangt eine ZWEITE, eigene Bestaetigung, sie passiert nicht mit einem Klick. Laesst sich eine Freigabe mit einem Klick rueckgaengig machen: S2.
A10: TF-F5 | B10: Steuernummer eines Kunden pflegen | C10: 1. Buero > Stammdaten 2. Kunden Almaty Fresh Market waehlen 3. Rechtsform TOO setzen (Feld heisst dann BIN) 4. Nummer eintragen, speichern 5. Gegenprobe mit ungueltigem Wert | D10: Rechtsform: TOO BIN gueltig: 190940001235 Gegenprobe ungueltig: 190940001231 | E10: Der gueltige Wert wird gespeichert. Der Gegenprobenwert wird mit Hinweis auf die PRUEFZIFFER abgelehnt. Bei Rechtsform TOO muss das Feld BIN heissen, nicht IIN.
A11: TF-F6 | B11: Reklamation bearbeiten und schliessen | C11: 1. Markt > Reklamationen 2. Vorgang aus TF-K5 oeffnen 3. "In Pruefung nehmen" 4. Nachricht hinzufuegen 5. "Annehmen", dann "Als erledigt abschliessen" | D11: Nachricht: TEST Gutschrift geprueft, Ware war bei Anlieferung zu warm | E11: Der Status durchlaeuft die Stufen sichtbar. Die Rueckverfolgung zeigt die urspruengliche Charge. Der Verlauf enthaelt die eigene Nachricht mit Zeitstempel.
A12: TF-F7 | B12: Kein Eingriff in den Feldbetrieb (NEGATIVTEST) | C12: 1. Navigation pruefen: erscheint Feld > Pflueckaufgaben? 2. Adresse aufrufen: /de/dashboard/feld/pflanzenschutz 3. Falls Pflueckaufgaben lesbar: nach "Neue Pflueckaufgabe" suchen | D12: direkter Adressaufruf | E12: Pflueckaufgaben sind hoechstens LESBAR, nicht anlegbar. Pflanzenschutz endet mit einer Zugriffsmeldung. Die Buchhaltung rechnet ab, sie plant keine Ernte. Laesst sich eine Aufgabe anlegen oder eine Behandlung erfassen: S2.
E14: Zwischenstand: | F14: =COUNTIF(F6:F12,"OK") | G14: OK von 7
F15: =COUNTIF(F6:F12,"NOK") | G15: NOK von 7
F16: =COUNTIF(F6:F12,"blockiert") | G16: blockiert von 7
A18: Freie Funde (alles Auffaellige ausserhalb der Testfaelle):
A24: Gesamteindruck in zwei Saetzen: Koennte diese Person damit arbeiten?

Sheet Brigade
A1: Damicon Testfaelle - Rolle: Brigade
A2: Anmeldung als: brigade@damicon.demo
A3: Arbeitet im Feld, am Telefon, oft ohne gutes Netz. MINDESTENS TF-B1 bis TF-B3 auf einem Handy oder in einem Browserfenster von etwa 390 px Breite durchgehen. TF-B1 braucht die Aufgabe aus TF-L1.
A5: Nr | B5: Was geprueft wird | C5: Schritte | D5: Testdaten (Eingabe) | E5: Erwartetes Ergebnis | F5: Ergebnis | G5: Beobachtung | H5: Datum / Tester
A6: TF-B1 | B6: Aufgabe annehmen und starten | C6: 1. Feld > Pflueckaufgaben 2. Aufgabe zu T-N-A-01 im Status "offen" oeffnen 3. "Aufgabe annehmen" 4. "Pfluecken starten" | D6: keine Eingabe | E6: Status wechselt offen > angenommen > in Arbeit. Jeder Schritt ist sofort sichtbar, ohne die Seite neu zu laden.
A7: TF-B2 | B7: Menge melden | C7: 1. Dieselbe Aufgabe oeffnen 2. Ist-Menge und Ausschuss eintragen 3. "Menge melden und zur Belegpruefung geben" | D7: Ist-Menge in kg: 118,5 Ausschuss in kg: 6 Pfluecker: D. Sarsenbaj | E7: Status wechselt auf "Belegpruefung". Die Mengen stehen wie eingegeben da, das Komma wurde nicht verschluckt (118,5 darf nicht zu 1185 werden).
A8: TF-B3 | B8: Fotobeleg hochladen (Pflicht) | C8: 1. Aufgabe oeffnen 2. Belegart waehlen 3. Bild waehlen, Hinweis eintragen 4. "Fotobeleg hochladen" | D8: Belegart: Steige Foto: beliebiges Bild vom Geraet Hinweis: TEST Verkaufsschale 125 g, geschlossene Fruchtdecke | E8: Das Bild erscheint als Beleg bei der Aufgabe, vorher stand dort ein Platzhalter. Ohne Beleg darf die Betriebsleitung in TF-L4 nicht abschliessen koennen.
A9: TF-B4 | B9: Uebergabequittung erfassen | C9: 1. Hof > Logistik 2. Eine geplante Lieferung oeffnen 3. Als zugestellt markieren, quittieren | D9: Empfaenger: TEST Gastro-Distributor Almaty Zeitpunkt: jetzt | E9: Die Lieferung gilt als zugestellt, die Quittung ist gespeichert und im Verlauf sichtbar.
A10: TF-B5 | B10: Neue Lieferung planen ist nicht erlaubt (NEGATIVTEST) | C10: 1. Hof > Logistik 2. Nach "Neue Lieferung", "Tour anlegen" o. Ae. suchen | D10: keine Eingabe | E10: Es gibt KEINE Schaltflaeche zum Anlegen einer neuen Lieferung. Die Brigade quittiert nur, geplant wird im Buero. Laesst sich eine Lieferung anlegen: S3.
A11: TF-B6 | B11: Kein Zugriff auf Finanzen und Lohn (NEGATIVTEST) | C11: 1. Navigation pruefen: erscheint Buero > Finanzen oder Lohn? 2. Adresse aufrufen: /de/dashboard/buero/finanzen | D11: direkter Adressaufruf | E11: Die Module tauchen in der Navigation NICHT auf. Der direkte Aufruf endet mit einer Zugriffsmeldung, nicht mit sichtbaren Zahlen. Werden Finanzdaten angezeigt: S1.
E13: Zwischenstand: | F13: =COUNTIF(F6:F11,"OK") | G13: OK von 6
F14: =COUNTIF(F6:F11,"NOK") | G14: NOK von 6
F15: =COUNTIF(F6:F11,"blockiert") | G15: blockiert von 6
A17: Freie Funde (alles Auffaellige ausserhalb der Testfaelle):
A23: Gesamteindruck in zwei Saetzen: Koennte diese Person damit arbeiten?

Sheet Pfluecker
A1: Damicon Testfaelle - Rolle: Pfluecker
A2: Anmeldung als: pfluecker@damicon.demo
A3: Schmalste Rolle: nur die EIGENE Leistung, der eigene Lohn, die eigene Einarbeitung. TF-P3 ist der wichtigste Test der ganzen Reihe, weil dort Lohndaten anderer Menschen im Spiel sind. Auf dem Handy pruefen, diese Rolle benutzt nie einen Schreibtischrechner.
A5: Nr | B5: Was geprueft wird | C5: Schritte | D5: Testdaten (Eingabe) | E5: Erwartetes Ergebnis | F5: Ergebnis | G5: Beobachtung | H5: Datum / Tester
A6: TF-P1 | B6: Nur drei Bereiche sichtbar | C6: 1. Anmelden 2. Navigation vollstaendig durchsehen | D6: keine Eingabe | E6: Sichtbar sind ausschliesslich Dashboard, Lohn und Schulungen. Keine Zone Feld, Hof oder Markt. Jeder zusaetzliche Eintrag ist ein Fund.
A7: TF-P2 | B7: Eigene Abrechnung einsehen | C7: 1. Lohn oeffnen 2. Eigene Abrechnung oeffnen 3. Positionen je Pflueckaufgabe ansehen | D7: keine Eingabe | E7: Die eigene Abrechnung ist sichtbar, mit Positionen, Qualitaetsfaktor und Nettobetrag. Die Zahlen sind nachvollziehbar dargestellt, nicht nur eine Endsumme.
A8: TF-P3 | B8: Fremde Abrechnungen sind unsichtbar (NEGATIVTEST, wichtigster Fall) | C8: 1. Lohn oeffnen 2. Liste zaehlen: wie viele Personen erscheinen? 3. Nach fremden Namen suchen 4. Falls Filter/Suche existiert, damit nach anderen Namen suchen | D8: Suchbegriff: Tulegenowa zweiter Versuch: Qojschybaj | E8: Es erscheint AUSSCHLIESSLICH die eigene Person. Kein zweiter Name, auch nicht ueber Suche oder Filter. Erscheint ein fremder Name mit Betrag: S1, sofort melden und NICHT weitertesten.
A9: TF-P4 | B9: Kurzeinarbeitung abhaken | C9: 1. Schulungen oeffnen 2. Kurzeinarbeitung oeffnen 3. Einen offenen Punkt abhaken 4. Seite neu laden | D9: Punkt: Hygiene und Handschuhe | E9: Der Haken bleibt nach dem Neuladen gesetzt, der Fortschritt steigt sichtbar. Zusatz: laesst sich die Einarbeitung auf Russisch oder Kasachisch umstellen?
A10: TF-P5 | B10: Kein Zugriff auf Pflueckaufgaben und Personal (NEGATIVTEST) | C10: 1. Adresse aufrufen: /de/dashboard/feld/pflueckaufgaben 2. Adresse aufrufen: /de/dashboard/buero/personal | D10: direkte Adressaufrufe | E10: Beide enden mit einer Zugriffsmeldung. Kein Blick auf Aufgaben anderer Brigaden, keine Personalliste. Werden Inhalte angezeigt: S1.
E12: Zwischenstand: | F12: =COUNTIF(F6:F10,"OK") | G12: OK von 5
F13: =COUNTIF(F6:F10,"NOK") | G13: NOK von 5
F14: =COUNTIF(F6:F10,"blockiert") | G14: blockiert von 5
A16: Freie Funde (alles Auffaellige ausserhalb der Testfaelle):
A22: Gesamteindruck in zwei Saetzen: Koennte diese Person damit arbeiten?

Sheet Erzeuger
A1: Damicon Testfaelle - Rolle: Erzeuger (Nachbarbetrieb)
A2: Anmeldung als: erzeuger@damicon.demo
A3: Ein Nachbarbetrieb, der seine Ware in den Aggregator verkauft. Er sieht die eigenen Lieferungen und die eigene Abrechnung, nicht den Betrieb der anderen.
A5: Nr | B5: Was geprueft wird | C5: Schritte | D5: Testdaten (Eingabe) | E5: Erwartetes Ergebnis | F5: Ergebnis | G5: Beobachtung | H5: Datum / Tester
A6: TF-E1 | B6: Eigene Lieferungen im Dashboard | C6: 1. Anmelden 2. Dashboard ansehen 3. Navigation durchsehen | D6: keine Eingabe | E6: Sichtbar sind Dashboard, Reihenbloecke, Pflueckaufgaben, Finanzen, Dokumente, Aggregator, B2B-Portal und Schulungen. Kein Lohn, kein Personal, keine Rollen.
A7: TF-E2 | B7: Nachbarbetrieb aufnehmen | C7: 1. Markt > Aggregator 2. "Nachbarbetrieb aufnehmen" 3. Felder fuellen, absenden | D7: Name: TEST Nachbarbetrieb Talgar Ort: Talgar Ansprechperson: R. Baitulin | E7: Der Betrieb erscheint in der Liste und steht danach beim Import in TF-E3 zur Auswahl.
A8: TF-E3 | B8: Zukauf per CSV importieren | C8: 1. Markt > Aggregator 2. "Zukauf importieren" 3. CSV-Daten einfuegen 4. "Pruefen und importieren" | D8: Nachbarbetrieb Kaskelen;Tulameen;140,5;2026-09-20 Nachbarbetrieb Uzynagash;Polka;88,0;2026-09-20 Nachbarbetrieb Kaskelen;Polana;61,25;2026-09-20 (Trennzeichen und Spaltenfolge an die Vorlage der Seite anpassen) | E8: Es erscheint zuerst eine PRUEFUNG, erst danach wird importiert. Summe 289,75 kg auf drei Chargen.
A9: TF-E4 | B9: Fehlerhafte CSV wird abgewiesen (NEGATIVTEST) | C9: 1. Wie TF-E3, aber mit fehlerhafter Zeile 2. "Pruefen und importieren" 3. Danach Liste pruefen: wurde die erste Zeile importiert? | D9: Nachbarbetrieb Kaskelen;Tulameen;140,5;2026-09-20 Unbekannter Betrieb XYZ;Polka;abc;2026-09-20 | E9: Der Import wird ABGELEHNT mit Hinweis auf die fehlerhafte Zeile (unbekannter Betrieb, Menge keine Zahl). Die erste, korrekte Zeile darf NICHT importiert worden sein, der Vorgang ist ganz oder gar nicht. Wurde sie importiert: S2.
A10: TF-E5 | B10: Kein Zugriff auf Lohn und Personal (NEGATIVTEST) | C10: 1. Adresse aufrufen: /de/dashboard/buero/lohn 2. Adresse aufrufen: /de/dashboard/buero/personal | D10: direkte Adressaufrufe | E10: Beide enden mit einer Zugriffsmeldung. Ein Nachbarbetrieb darf weder Loehne noch Personal des Hauptbetriebs sehen. Werden Inhalte angezeigt: S1.
E12: Zwischenstand: | F12: =COUNTIF(F6:F10,"OK") | G12: OK von 5
F13: =COUNTIF(F6:F10,"NOK") | G13: NOK von 5
F14: =COUNTIF(F6:F10,"blockiert") | G14: blockiert von 5
A16: Freie Funde (alles Auffaellige ausserhalb der Testfaelle):
A22: Gesamteindruck in zwei Saetzen: Koennte diese Person damit arbeiten?

Sheet Kunde
A1: Damicon Testfaelle - Rolle: B2B-Kunde
A2: Anmeldung als: entsteht in TF-K1, ersatzweise kunde@damicon.demo
A3: Einzige Rolle, die von aussen kommt und sich ueber eine Einladung selbst anlegt. TF-K1 braucht den Code aus TF-A2. Diese Rolle sieht ein Aussenstehender, Verstaendlichkeit zaehlt hier genauso wie Richtigkeit. TF-K7 laeuft ABGEMELDET.
A5: Nr | B5: Was geprueft wird | C5: Schritte | D5: Testdaten (Eingabe) | E5: Erwartetes Ergebnis | F5: Ergebnis | G5: Beobachtung | H5: Datum / Tester
A6: TF-K1 | B6: Einladung einloesen und Konto anlegen | C6: 1. /de/einladung oeffnen 2. Code aus TF-A2 VON HAND eintippen 3. Passwort vergeben, Konto anlegen, anmelden 4. Gegenprobe a: Code klein und ohne Bindestriche 5. Gegenprobe b: denselben Code ein zweites Mal einloesen | D6: Code: aus TF-A2 E-Mail: test.kunde.20092026@example.com Passwort: TestKunde2026! | E6: Konto entsteht, Anmeldung gelingt. Gegenprobe a wird trotzdem angenommen (Schreibweise wird abgefangen). Gegenprobe b wird ABGELEHNT, der Code ist verbraucht. Zusatz: der Code darf NICHT per ?code= in der Adresszeile vorbelegbar sein. Geht das: S2.
A7: TF-K2 | B7: Sortenkatalog ansehen | C7: 1. Markt > Sortenkatalog 2. Sorte Tulameen oeffnen | D7: keine Eingabe | E7: Sortenname, Typ, Erntefenster und Schalengroesse sind sichtbar und verstaendlich. Keine internen Kennungen wie Datenbank-IDs.
A8: TF-K3 | B8: Vorbestellung aufgeben | C8: 1. Markt > B2B-Portal 2. "Vorbestellung aufgeben" 3. Felder fuellen, absenden | D8: Sorte: Tulameen Menge: 45 kg Wunschtermin: in 7 Tagen Bemerkung: TEST Vorbestellung 20.09. | E8: Die Vorbestellung erscheint mit Status "angefragt", nicht automatisch bestaetigt. Das Buero bestaetigt von Hand, das ist so gewollt.
A9: TF-K4 | B9: Eigene Lieferungen und Rechnungshistorie | C9: 1. Markt > B2B-Portal 2. "Meine Lieferungen" 3. "Rechnungshistorie (Proforma)" 4. "Preisliste" | D9: keine Eingabe | E9: Sichtbar sind NUR die eigenen Lieferungen und Rechnungen, keine anderer Kunden. Die Preisliste zeigt die Preise der eigenen Kundengruppe. Erscheint ein fremder Kundenname: S1.
A10: TF-K5 | B10: Reklamation melden | C10: 1. Markt > Reklamationen 2. "Reklamation melden" 3. Felder fuellen, absenden | D10: Grund: Ware bei Anlieferung zu warm Betreff: TEST Reklamation 20.09. Beschreibung: Kerntemperatur bei Anlieferung 11 Grad statt maximal 4 Grad. Betroffene Menge: 12 kg Charge: eine aus "Meine Lieferungen" | E10: Der Vorgang wird angelegt und erscheint im eigenen Verlauf. Eine Frist wird gesetzt (automatisch 5 Tage, falls nichts eingetragen). Wird in TF-F6 weiterbearbeitet.
A11: TF-K6 | B11: Reklamation nicht selbst schliessen (NEGATIVTEST) | C11: 1. Eigene Reklamation aus TF-K5 oeffnen 2. Nach "Annehmen", "Ablehnen" oder "Als erledigt abschliessen" suchen | D11: keine Eingabe | E11: Diese Schaltflaechen fehlen. Der Kunde meldet und verfolgt, entschieden wird im Buero. Kann der Kunde die eigene Reklamation selbst schliessen: S2.
A12: TF-K7 | B12: Herkunft ohne Anmeldung, aber ohne Geheimnisse (ABGEMELDET) | C12: 1. Abmelden, privates Fenster oeffnen 2. /de/herkunft/<Code> aufrufen 3. Seite vollstaendig durchlesen | D12: Steigen- oder Liefercode aus TF-K4 | E12: Sichtbar: WO gewachsen, WANN gepflueckt, ob die Kuehlkette gehalten hat. NICHT sichtbar: Name des Pflueckers, Menge, Preis. Erscheint eines dieser drei: S1.
E14: Zwischenstand: | F14: =COUNTIF(F6:F12,"OK") | G14: OK von 7
F15: =COUNTIF(F6:F12,"NOK") | G15: NOK von 7
F16: =COUNTIF(F6:F12,"blockiert") | G16: blockiert von 7
A18: Freie Funde (alles Auffaellige ausserhalb der Testfaelle):
A24: Gesamteindruck in zwei Saetzen: Koennte diese Person damit arbeiten?

Sheet Funde
A1: Fundliste - hier kommen alle NOK und alle freien Funde zusammen
A3: Nr | B3: Testfall | C3: Rolle | D3: Klasse S1-S4 | E3: Was passiert ist | F3: Erwartet war | G3: Bildschirmfoto | H3: Status
A4: 1 | B4: TF-P3 | C4: Pfluecker | D4: S1 | E4: BEISPIEL - vor Abgabe loeschen: In der Lohnliste erschien neben der eigenen Zeile auch A. Tulegenowa mit 186.400 Tenge netto. | F4: Nur die eigene Person darf erscheinen. | G4: TF-P3.png | H4: offen
